This image shows a terminal displaying an error during script execution (`uv run ...`). A `PermissionError` occurred because the script tried to create `/data!`, but was denied permission. This specific failure happened when calling `os.makedirs()` at line 284 of the temporary Python file generated from this GitHub link: https://raw.githubusercontent.com/sanand/tools-in-data-science-public/tds-2025-01/project-1/datagen.py